batch 0 --- Loss: 0.1377
batch 1 --- Loss: 0.1282
batch 2 --- Loss: 0.1105
batch 3 --- Loss: 0.0911
C:\Users\Alienware\AppData\Local\Programs\Python\Python311\Lib\site-packages\torch\functional.py:504: UserWarning: torch.meshgrid: in an upcoming release, it will be required to pass the indexing argument. (Triggered internally at ..\aten\src\ATen\native\TensorShape.cpp:3484.)
  return _VF.meshgrid(tensors, **kwargs)  # type: ignore[attr-defined]
C:\Users\Alienware\AppData\Local\Programs\Python\Python311\Lib\site-packages\torch\nn\functional.py:4236: UserWarning: Default grid_sample and affine_grid behavior has changed to align_corners=False since 1.3.0. Please specify align_corners=True if the old behavior is desired. See the documentation of grid_sample for details.
  warnings.warn(
batch 4 --- Loss: 0.0681
batch 5 --- Loss: 0.0552
batch 6 --- Loss: 0.0351
batch 7 --- Loss: 0.0281
Epoch 1 / 5 --- Loss: 0.0872
Accuracy: 1.0000 ---- Loss: 0.1155
batch 0 --- Loss: 0.0184
batch 1 --- Loss: 0.0111
batch 2 --- Loss: 0.0081
batch 3 --- Loss: 0.0068
batch 4 --- Loss: 0.0079
batch 5 --- Loss: 0.0043
batch 6 --- Loss: 0.0032
batch 7 --- Loss: 0.0030
Epoch 2 / 5 --- Loss: 0.0084
Accuracy: 1.0000 ---- Loss: 0.0290
batch 0 --- Loss: 0.0022
batch 1 --- Loss: 0.0018
batch 2 --- Loss: 0.0016
batch 3 --- Loss: 0.0016
batch 4 --- Loss: 0.0015
batch 5 --- Loss: 0.0013
batch 6 --- Loss: 0.0013
batch 7 --- Loss: 0.0012
Epoch 3 / 5 --- Loss: 0.0017
Accuracy: 1.0000 ---- Loss: 0.0023
batch 0 --- Loss: 0.0012
batch 1 --- Loss: 0.0011
batch 2 --- Loss: 0.0011
batch 3 --- Loss: 0.0010
batch 4 --- Loss: 0.0010
batch 5 --- Loss: 0.0010
batch 6 --- Loss: 0.0009
batch 7 --- Loss: 0.0009
Epoch 4 / 5 --- Loss: 0.0011
Accuracy: 1.0000 ---- Loss: 0.0009
batch 0 --- Loss: 0.0009
batch 1 --- Loss: 0.0008
batch 2 --- Loss: 0.0008
batch 3 --- Loss: 0.0008
batch 4 --- Loss: 0.0008
batch 5 --- Loss: 0.0007
batch 6 --- Loss: 0.0007
batch 7 --- Loss: 0.0007
Epoch 5 / 5 --- Loss: 0.0008
Accuracy: 1.0000 ---- Loss: 0.0007
Traceback (most recent call last):
  File "c:\Users\Alienware\Desktop\VC CMPT742\A2\assignment_2\train.py", line 162, in <module>
    wandb.save('checkpoint.pt')
  File "C:\Users\Alienware\AppData\Local\Programs\Python\Python311\Lib\site-packages\wandb\sdk\wandb_run.py", line 370, in wrapper_fn
    return func(self, *args, **kwargs)
           ^^^^^^^^^^^^^^^^^^^^^^^^^^^
  File "C:\Users\Alienware\AppData\Local\Programs\Python\Python311\Lib\site-packages\wandb\sdk\wandb_run.py", line 360, in wrapper
    return func(self, *args, **kwargs)
           ^^^^^^^^^^^^^^^^^^^^^^^^^^^
  File "C:\Users\Alienware\AppData\Local\Programs\Python\Python311\Lib\site-packages\wandb\sdk\wandb_run.py", line 1824, in save
    return self._save(glob_str, base_path, policy)
           ^^^^^^^^^^^^^^^^^^^^^^^^^^^^^^^^^^^^^^^
  File "C:\Users\Alienware\AppData\Local\Programs\Python\Python311\Lib\site-packages\wandb\sdk\wandb_run.py", line 1878, in _save
    os.symlink(abs_path, wandb_path)
OSError: [WinError 1314] 客户端没有所需的特权。: 'C:\\Users\\Alienware\\Desktop\\VC CMPT742\\A2\\checkpoint.pt' -> 'C:\\Users\\Alienware\\Desktop\\VC CMPT742\\A2\\wandb\\run-20231024_222821-5n4xxg7o\\files\\checkpoint.pt'